<robot name = "robot">
    <joint name="Torso_Aardvark" type="revolute">
       <parent link="Torso"/>
       <child  link="Aardvark"/>
       <origin rpy="0 0 0" xyz="-0.883508325970731 0 3" />
     <axis xyz="0 1 0"/>
       <limit effort="0.0" lower="-3.14159" upper="3.14159" velocity="0.0"/>
    </joint>
    <joint name="Aardvark_Abacus" type="revolute">
       <parent link="Aardvark"/>
       <child  link="Abacus"/>
       <origin rpy="0 0 0" xyz="1.5588980699403798 0 0" />
     <axis xyz="0 1 0"/>
       <limit effort="0.0" lower="-3.14159" upper="3.14159" velocity="0.0"/>
    </joint>
    <joint name="Abacus_Abbey" type="revolute">
       <parent link="Abacus"/>
       <child  link="Abbey"/>
       <origin rpy="0 0 0" xyz="0.3217235663158562 0 0.016617488101808298" />
     <axis xyz="0 1 0"/>
       <limit effort="0.0" lower="-3.14159" upper="3.14159" velocity="0.0"/>
    </joint>
    <joint name="Abbey_Abdomen" type="revolute">
       <parent link="Abbey"/>
       <child  link="Abdomen"/>
       <origin rpy="0 0 0" xyz="0.7412328700016664 0 0" />
     <axis xyz="0 1 0"/>
       <limit effort="0.0" lower="-3.14159" upper="3.14159" velocity="0.0"/>
    </joint>
    <joint name="Abdomen_Cabin" type="revolute">
       <parent link="Abdomen"/>
       <child  link="Cabin"/>
       <origin rpy="0 0 0" xyz="0.19184082216571907 0.4923927740838068 0" />
     <axis xyz="0 1 0"/>
       <limit effort="0.0" lower="-3.14159" upper="3.14159" velocity="0.0"/>
    </joint>
    <link name="Torso">
        <inertial>
            <origin xyz="-1 0 3" rpy="0 0 0"/>
            <mass value="1" />
            <inertia ixx="100" ixy="0" ixz="0" iyy="100" iyz="0" izz="100" />
        </inertial>
        <visual>
            <origin xyz="-1 0 3" rpy="0 0 0"/>
            <geometry>
                <box size="0.23298334805853793 1 1" />
            </geometry>
            <material name="Cyan">
                <color rgba="0 1.0 1.0 1.0"/>
            </material>
        </visual>
        <collision>
            <origin xyz="-1 0 3" rpy="0 0 0"/>
            <geometry>
                <box size="0.23298334805853793 1 1" />
            </geometry>
        </collision>
    </link>
    <link name="Aardvark">
        <inertial>
            <origin xyz="0.7794490349701899 0 0" rpy="0 0 0"/>
            <mass value="1" />
            <inertia ixx="100" ixy="0" ixz="0" iyy="100" iyz="0" izz="100" />
        </inertial>
        <visual>
            <origin xyz="0.7794490349701899 0 0" rpy="0 0 0"/>
            <geometry>
                <box size="1.5588980699403798 3.4509708187025705 0.788328176027985" />
            </geometry>
            <material name="Green">
                <color rgba="0 1.0 0 1.0"/>
            </material>
        </visual>
        <collision>
            <origin xyz="0.7794490349701899 0 0" rpy="0 0 0"/>
            <geometry>
                <box size="1.5588980699403798 3.4509708187025705 0.788328176027985" />
            </geometry>
        </collision>
    </link>
    <link name="Abacus">
        <inertial>
            <origin xyz="0 0 0.016617488101808298" rpy="0 0 0"/>
            <mass value="1" />
            <inertia ixx="100" ixy="0" ixz="0" iyy="100" iyz="0" izz="100" />
        </inertial>
        <visual>
            <origin xyz="0 0 0.016617488101808298" rpy="0 0 0"/>
            <geometry>
                <box size="0.6434471326317124 0.37537935662467037 0.033234976203616595" />
            </geometry>
            <material name="Cyan">
                <color rgba="0 1.0 1.0 1.0"/>
            </material>
        </visual>
        <collision>
            <origin xyz="0 0 0.016617488101808298" rpy="0 0 0"/>
            <geometry>
                <box size="0.6434471326317124 0.37537935662467037 0.033234976203616595" />
            </geometry>
        </collision>
    </link>
    <link name="Abbey">
        <inertial>
            <origin xyz="0.3706164350008332 0 0" rpy="0 0 0"/>
            <mass value="1" />
            <inertia ixx="100" ixy="0" ixz="0" iyy="100" iyz="0" izz="100" />
        </inertial>
        <visual>
            <origin xyz="0.3706164350008332 0 0" rpy="0 0 0"/>
            <geometry>
                <box size="0.7412328700016664 0.6238117167462895 1.111727315108588" />
            </geometry>
            <material name="Green">
                <color rgba="0 1.0 0 1.0"/>
            </material>
        </visual>
        <collision>
            <origin xyz="0.3706164350008332 0 0" rpy="0 0 0"/>
            <geometry>
                <box size="0.7412328700016664 0.6238117167462895 1.111727315108588" />
            </geometry>
        </collision>
    </link>
    <link name="Abdomen">
        <inertial>
            <origin xyz="0.19184082216571907 0 0" rpy="0 0 0"/>
            <mass value="1" />
            <inertia ixx="100" ixy="0" ixz="0" iyy="100" iyz="0" izz="100" />
        </inertial>
        <visual>
            <origin xyz="0.19184082216571907 0 0" rpy="0 0 0"/>
            <geometry>
                <box size="0.38368164433143814 0.9847855481676135 0.8903520302193797" />
            </geometry>
            <material name="Green">
                <color rgba="0 1.0 0 1.0"/>
            </material>
        </visual>
        <collision>
            <origin xyz="0.19184082216571907 0 0" rpy="0 0 0"/>
            <geometry>
                <box size="0.38368164433143814 0.9847855481676135 0.8903520302193797" />
            </geometry>
        </collision>
    </link>
    <link name="Cabin">
        <inertial>
            <origin xyz="0 1.185717430442004 0" rpy="0 0 0"/>
            <mass value="1" />
            <inertia ixx="100" ixy="0" ixz="0" iyy="100" iyz="0" izz="100" />
        </inertial>
        <visual>
            <origin xyz="0 1.185717430442004 0" rpy="0 0 0"/>
            <geometry>
                <box size="2.5505071460355158 2.371434860884008 2.065700995870943" />
            </geometry>
            <material name="Ryan">
                <color rgba="0 0 0.5 1"/>
            </material>
        </visual>
        <collision>
            <origin xyz="0 1.185717430442004 0" rpy="0 0 0"/>
            <geometry>
                <box size="2.5505071460355158 2.371434860884008 2.065700995870943" />
            </geometry>
        </collision>
    </link>
</robot>