<robot name = "robot">
    <link name="Torso">
        <inertial>
            <origin xyz="-4 0 3" rpy="0 0 0"/>
            <mass value="1" />
            <inertia ixx="100" ixy="0" ixz="0" iyy="100" iyz="0" izz="100" />
        </inertial>
        <visual>
            <origin xyz="-4 0 3" rpy="0 0 0"/>
            <geometry>
                <box size="0.8621529399251151 1 1" />
            </geometry>
            <material name="Green">
                <color rgba="0 1.0 0 1.0"/>
            </material>
        </visual>
        <collision>
            <origin xyz="-4 0 3" rpy="0 0 0"/>
            <geometry>
                <box size="0.8621529399251151 1 1" />
            </geometry>
        </collision>
    </link>
    <joint name="Torso_Apple" type="revolute">
       <parent link="Torso"/>
       <child  link="Apple"/>
       <origin rpy="0 0 0" xyz="-3.5689235300374422 0 3" />
     <axis xyz="0 1 0"/>
       <limit effort="0.0" lower="-3.14159" upper="3.14159" velocity="0.0"/>
    </joint>
    <link name="Apple">
        <inertial>
            <origin xyz="0.28631879340327515 0 0" rpy="0 0 0"/>
            <mass value="1" />
            <inertia ixx="100" ixy="0" ixz="0" iyy="100" iyz="0" izz="100" />
        </inertial>
        <visual>
            <origin xyz="0.28631879340327515 0 0" rpy="0 0 0"/>
            <geometry>
                <box size="0.5726375868065503 3.2453103831558328 2.291157374883737" />
            </geometry>
            <material name="Cyan">
                <color rgba="0 1.0 1.0 1.0"/>
            </material>
        </visual>
        <collision>
            <origin xyz="0.28631879340327515 0 0" rpy="0 0 0"/>
            <geometry>
                <box size="0.5726375868065503 3.2453103831558328 2.291157374883737" />
            </geometry>
        </collision>
    </link>
    <link name="Dog">
        <inertial>
            <origin xyz="0 0 0.7790766740370016" rpy="0 0 0"/>
            <mass value="1" />
            <inertia ixx="100" ixy="0" ixz="0" iyy="100" iyz="0" izz="100" />
        </inertial>
        <visual>
            <origin xyz="0 0 0.7790766740370016" rpy="0 0 0"/>
            <geometry>
                <box size="0.9665164315475634 0.8953434476834967 1.5581533480740033" />
            </geometry>
            <material name="Cyan">
                <color rgba="0 1.0 1.0 1.0"/>
            </material>
        </visual>
        <collision>
            <origin xyz="0 0 0.7790766740370016" rpy="0 0 0"/>
            <geometry>
                <box size="0.9665164315475634 0.8953434476834967 1.5581533480740033" />
            </geometry>
        </collision>
    </link>
    <joint name="Apple_Dog" type="revolute">
       <parent link="Apple"/>
       <child  link="Dog"/>
       <origin rpy="0 0 0" xyz="0.5726375868065503 0 0" />
     <axis xyz="0 1 0"/>
       <limit effort="0.0" lower="-3.14159" upper="3.14159" velocity="0.0"/>
    </joint>
    <link name="Person">
        <inertial>
            <origin xyz="0 0 0.4435590434838015" rpy="0 0 0"/>
            <mass value="1" />
            <inertia ixx="100" ixy="0" ixz="0" iyy="100" iyz="0" izz="100" />
        </inertial>
        <visual>
            <origin xyz="0 0 0.4435590434838015" rpy="0 0 0"/>
            <geometry>
                <box size="1.196671115526762 1.3738867190881363 0.887118086967603" />
            </geometry>
            <material name="Cyan">
                <color rgba="0 1.0 1.0 1.0"/>
            </material>
        </visual>
        <collision>
            <origin xyz="0 0 0.4435590434838015" rpy="0 0 0"/>
            <geometry>
                <box size="1.196671115526762 1.3738867190881363 0.887118086967603" />
            </geometry>
        </collision>
    </link>
    <joint name="Dog_Person" type="revolute">
       <parent link="Dog"/>
       <child  link="Person"/>
       <origin rpy="0 0 0" xyz="0 0 1.5581533480740033" />
     <axis xyz="0 1 0"/>
       <limit effort="0.0" lower="-3.14159" upper="3.14159" velocity="0.0"/>
    </joint>
    <link name="Fox">
        <inertial>
            <origin xyz="0.2532036292972554 0 0" rpy="0 0 0"/>
            <mass value="1" />
            <inertia ixx="100" ixy="0" ixz="0" iyy="100" iyz="0" izz="100" />
        </inertial>
        <visual>
            <origin xyz="0.2532036292972554 0 0" rpy="0 0 0"/>
            <geometry>
                <box size="0.5064072585945107 0.9281959503145367 1.4543463526079956" />
            </geometry>
            <material name="Cyan">
                <color rgba="0 1.0 1.0 1.0"/>
            </material>
        </visual>
        <collision>
            <origin xyz="0.2532036292972554 0 0" rpy="0 0 0"/>
            <geometry>
                <box size="0.5064072585945107 0.9281959503145367 1.4543463526079956" />
            </geometry>
        </collision>
    </link>
    <joint name="Person_Fox" type="revolute">
       <parent link="Person"/>
       <child  link="Fox"/>
       <origin rpy="0 0 0" xyz="0.598335557763381 0 0.4435590434838015" />
     <axis xyz="0 1 0"/>
       <limit effort="0.0" lower="-3.14159" upper="3.14159" velocity="0.0"/>
    </joint>
    <link name="Flower">
        <inertial>
            <origin xyz="0.42521438475600215 0 0" rpy="0 0 0"/>
            <mass value="1" />
            <inertia ixx="100" ixy="0" ixz="0" iyy="100" iyz="0" izz="100" />
        </inertial>
        <visual>
            <origin xyz="0.42521438475600215 0 0" rpy="0 0 0"/>
            <geometry>
                <box size="0.8504287695120043 0.018102732577588432 0.4393785790318985" />
            </geometry>
            <material name="Green">
                <color rgba="0 1.0 0 1.0"/>
            </material>
        </visual>
        <collision>
            <origin xyz="0.42521438475600215 0 0" rpy="0 0 0"/>
            <geometry>
                <box size="0.8504287695120043 0.018102732577588432 0.4393785790318985" />
            </geometry>
        </collision>
    </link>
    <joint name="Fox_Flower" type="revolute">
       <parent link="Fox"/>
       <child  link="Flower"/>
       <origin rpy="0 0 0" xyz="0.5064072585945107 0 0" />
     <axis xyz="0 1 0"/>
       <limit effort="0.0" lower="-3.14159" upper="3.14159" velocity="0.0"/>
    </joint>
</robot>