<robot name = "robot">
    <link name="Torso">
        <inertial>
            <origin xyz="2 0 3" rpy="0 0 0"/>
            <mass value="1" />
            <inertia ixx="100" ixy="0" ixz="0" iyy="100" iyz="0" izz="100" />
        </inertial>
        <visual>
            <origin xyz="2 0 3" rpy="0 0 0"/>
            <geometry>
                <box size="1.707322726675308 1 1" />
            </geometry>
            <material name="Cyan">
                <color rgba="0 1.0 1.0 1.0"/>
            </material>
        </visual>
        <collision>
            <origin xyz="2 0 3" rpy="0 0 0"/>
            <geometry>
                <box size="1.707322726675308 1 1" />
            </geometry>
        </collision>
    </link>
    <link name="Apple">
        <inertial>
            <origin xyz="1.8191176024613682 0 0" rpy="0 0 0"/>
            <mass value="1" />
            <inertia ixx="100" ixy="0" ixz="0" iyy="100" iyz="0" izz="100" />
        </inertial>
        <visual>
            <origin xyz="1.8191176024613682 0 0" rpy="0 0 0"/>
            <geometry>
                <box size="3.6382352049227364 2.9373267310782825 3.2062377149119285" />
            </geometry>
            <material name="Green">
                <color rgba="0 1.0 0 1.0"/>
            </material>
        </visual>
        <collision>
            <origin xyz="1.8191176024613682 0 0" rpy="0 0 0"/>
            <geometry>
                <box size="3.6382352049227364 2.9373267310782825 3.2062377149119285" />
            </geometry>
        </collision>
    </link>
    <link name="Dog">
        <inertial>
            <origin xyz="0 0.9135879932535625 0" rpy="0 0 0"/>
            <mass value="1" />
            <inertia ixx="100" ixy="0" ixz="0" iyy="100" iyz="0" izz="100" />
        </inertial>
        <visual>
            <origin xyz="0 0.9135879932535625 0" rpy="0 0 0"/>
            <geometry>
                <box size="1.7381652761476019 1.827175986507125 0.284472383896345" />
            </geometry>
            <material name="Green">
                <color rgba="0 1.0 0 1.0"/>
            </material>
        </visual>
        <collision>
            <origin xyz="0 0.9135879932535625 0" rpy="0 0 0"/>
            <geometry>
                <box size="1.7381652761476019 1.827175986507125 0.284472383896345" />
            </geometry>
        </collision>
    </link>
    <link name="Person">
        <inertial>
            <origin xyz="0.5589909549325245 0 0" rpy="0 0 0"/>
            <mass value="1" />
            <inertia ixx="100" ixy="0" ixz="0" iyy="100" iyz="0" izz="100" />
        </inertial>
        <visual>
            <origin xyz="0.5589909549325245 0 0" rpy="0 0 0"/>
            <geometry>
                <box size="1.117981909865049 0.8085118156231368 0.16764967507398842" />
            </geometry>
            <material name="Cyan">
                <color rgba="0 1.0 1.0 1.0"/>
            </material>
        </visual>
        <collision>
            <origin xyz="0.5589909549325245 0 0" rpy="0 0 0"/>
            <geometry>
                <box size="1.117981909865049 0.8085118156231368 0.16764967507398842" />
            </geometry>
        </collision>
    </link>
    <link name="Fox">
        <inertial>
            <origin xyz="0 0 0.48666556695688523" rpy="0 0 0"/>
            <mass value="1" />
            <inertia ixx="100" ixy="0" ixz="0" iyy="100" iyz="0" izz="100" />
        </inertial>
        <visual>
            <origin xyz="0 0 0.48666556695688523" rpy="0 0 0"/>
            <geometry>
                <box size="0.1279571947386804 1.3191856408663463 0.9733311339137705" />
            </geometry>
            <material name="Green">
                <color rgba="0 1.0 0 1.0"/>
            </material>
        </visual>
        <collision>
            <origin xyz="0 0 0.48666556695688523" rpy="0 0 0"/>
            <geometry>
                <box size="0.1279571947386804 1.3191856408663463 0.9733311339137705" />
            </geometry>
        </collision>
    </link>
    <link name="Flower">
        <inertial>
            <origin xyz="0 0 0.292825378247198" rpy="0 0 0"/>
            <mass value="1" />
            <inertia ixx="100" ixy="0" ixz="0" iyy="100" iyz="0" izz="100" />
        </inertial>
        <visual>
            <origin xyz="0 0 0.292825378247198" rpy="0 0 0"/>
            <geometry>
                <box size="1.9446240787865843 0.6809254657140362 0.585650756494396" />
            </geometry>
            <material name="Green">
                <color rgba="0 1.0 0 1.0"/>
            </material>
        </visual>
        <collision>
            <origin xyz="0 0 0.292825378247198" rpy="0 0 0"/>
            <geometry>
                <box size="1.9446240787865843 0.6809254657140362 0.585650756494396" />
            </geometry>
        </collision>
    </link>
    <joint name="Torso_Apple" type="revolute">
       <parent link="Torso"/>
       <child  link="Apple"/>
       <origin rpy="0 0 0" xyz="2.853661363337654 0 3" />
     <axis xyz="0 1 0"/>
       <limit effort="0.0" lower="-3.14159" upper="3.14159" velocity="0.0"/>
    </joint>
    <joint name="Apple_Dog" type="revolute">
       <parent link="Apple"/>
       <child  link="Dog"/>
       <origin rpy="0 0 0" xyz="3.6382352049227364 0 0" />
     <axis xyz="0 1 0"/>
       <limit effort="0.0" lower="-3.14159" upper="3.14159" velocity="0.0"/>
    </joint>
    <joint name="Dog_Person" type="revolute">
       <parent link="Dog"/>
       <child  link="Person"/>
       <origin rpy="0 0 0" xyz="0.8690826380738009 0.9135879932535625 0" />
     <axis xyz="0 1 0"/>
       <limit effort="0.0" lower="-3.14159" upper="3.14159" velocity="0.0"/>
    </joint>
    <joint name="Person_Fox" type="revolute">
       <parent link="Person"/>
       <child  link="Fox"/>
       <origin rpy="0 0 0" xyz="0.5589909549325245 0 0.08382483753699421" />
     <axis xyz="0 1 0"/>
       <limit effort="0.0" lower="-3.14159" upper="3.14159" velocity="0.0"/>
    </joint>
    <joint name="Fox_Flower" type="revolute">
       <parent link="Fox"/>
       <child  link="Flower"/>
       <origin rpy="0 0 0" xyz="0 0 0.9733311339137705" />
     <axis xyz="0 1 0"/>
       <limit effort="0.0" lower="-3.14159" upper="3.14159" velocity="0.0"/>
    </joint>
</robot>