<robot name = "robot">
    <link name="Torso">
        <inertial>
            <origin xyz="-2 0 3" rpy="0 0 0"/>
            <mass value="1" />
            <inertia ixx="100" ixy="0" ixz="0" iyy="100" iyz="0" izz="100" />
        </inertial>
        <visual>
            <origin xyz="-2 0 3" rpy="0 0 0"/>
            <geometry>
                <box size="0.6612368025007893 1 1" />
            </geometry>
            <material name="Green">
                <color rgba="0 1.0 0 1.0"/>
            </material>
        </visual>
        <collision>
            <origin xyz="-2 0 3" rpy="0 0 0"/>
            <geometry>
                <box size="0.6612368025007893 1 1" />
            </geometry>
        </collision>
    </link>
    <link name="Dog">
        <inertial>
            <origin xyz="0.1332168611576121 0.8404514147207107 0.6373998213139636" rpy="0 0 0"/>
            <mass value="1" />
            <inertia ixx="100" ixy="0" ixz="0" iyy="100" iyz="0" izz="100" />
        </inertial>
        <visual>
            <origin xyz="0.1332168611576121 0.8404514147207107 0.6373998213139636" rpy="0 0 0"/>
            <geometry>
                <box size="0.2664337223152242 1.6809028294414214 1.274799642627927" />
            </geometry>
            <material name="Green">
                <color rgba="0 1.0 0 1.0"/>
            </material>
        </visual>
        <collision>
            <origin xyz="0.1332168611576121 0.8404514147207107 0.6373998213139636" rpy="0 0 0"/>
            <geometry>
                <box size="0.2664337223152242 1.6809028294414214 1.274799642627927" />
            </geometry>
        </collision>
    </link>
    <joint name="Torso_Dog" type="revolute">
       <parent link="Torso"/>
       <child  link="Dog"/>
       <origin rpy="0 0 0" xyz="-1.6693815987496055 0 3" />
     <axis xyz="0 1 0"/>
       <limit effort="0.0" lower="-3.14159" upper="3.14159" velocity="0.0"/>
    </joint>
    <joint name="Torso_Dog" type="revolute">
       <parent link="Torso"/>
       <child  link="Dog"/>
       <origin rpy="0 0 0" xyz="0 0.5 0" />
     <axis xyz="0 1 0"/>
       <limit effort="0.0" lower="-3.14159" upper="3.14159" velocity="0.0"/>
    </joint>
</robot>