<robot name = "robot">
    <link name="Torso">
        <inertial>
            <origin xyz="1 0 3" rpy="0 0 0"/>
            <mass value="1" />
            <inertia ixx="100" ixy="0" ixz="0" iyy="100" iyz="0" izz="100" />
        </inertial>
        <visual>
            <origin xyz="1 0 3" rpy="0 0 0"/>
            <geometry>
                <box size="0.8050706145914097 1 1" />
            </geometry>
            <material name="Green">
                <color rgba="0 1.0 0 1.0"/>
            </material>
        </visual>
        <collision>
            <origin xyz="1 0 3" rpy="0 0 0"/>
            <geometry>
                <box size="0.8050706145914097 1 1" />
            </geometry>
        </collision>
    </link>
    <joint name="Torso_Apple" type="revolute">
       <parent link="Torso"/>
       <child  link="Apple"/>
       <origin rpy="0 0 0" xyz="1.4025353072957047 0 3" />
     <axis xyz="0 1 0"/>
       <limit effort="0.0" lower="-3.14159" upper="3.14159" velocity="0.0"/>
    </joint>
    <link name="Apple">
        <inertial>
            <origin xyz="0.20246150740783886 0 0" rpy="0 0 0"/>
            <mass value="1" />
            <inertia ixx="100" ixy="0" ixz="0" iyy="100" iyz="0" izz="100" />
        </inertial>
        <visual>
            <origin xyz="0.20246150740783886 0 0" rpy="0 0 0"/>
            <geometry>
                <box size="0.4049230148156777 0.7422121128647636 1.1019353854825014" />
            </geometry>
            <material name="Cyan">
                <color rgba="0 1.0 1.0 1.0"/>
            </material>
        </visual>
        <collision>
            <origin xyz="0.20246150740783886 0 0" rpy="0 0 0"/>
            <geometry>
                <box size="0.4049230148156777 0.7422121128647636 1.1019353854825014" />
            </geometry>
        </collision>
    </link>
    <link name="Dog">
        <inertial>
            <origin xyz="0 0.22006450268318345 0" rpy="0 0 0"/>
            <mass value="1" />
            <inertia ixx="100" ixy="0" ixz="0" iyy="100" iyz="0" izz="100" />
        </inertial>
        <visual>
            <origin xyz="0 0.22006450268318345 0" rpy="0 0 0"/>
            <geometry>
                <box size="1.5409871614434825 0.4401290053663669 0.8959087998005193" />
            </geometry>
            <material name="Green">
                <color rgba="0 1.0 0 1.0"/>
            </material>
        </visual>
        <collision>
            <origin xyz="0 0.22006450268318345 0" rpy="0 0 0"/>
            <geometry>
                <box size="1.5409871614434825 0.4401290053663669 0.8959087998005193" />
            </geometry>
        </collision>
    </link>
    <joint name="Torso_Dog" type="revolute">
       <parent link="Torso"/>
       <child  link="Dog"/>
       <origin rpy="0 0 0" xyz="0.40253530729570486 0.5 0" />
     <axis xyz="0 1 0"/>
       <limit effort="0.0" lower="-3.14159" upper="3.14159" velocity="0.0"/>
    </joint>
    <link name="Person">
        <inertial>
            <origin xyz="0 0 0.12679398128200803" rpy="0 0 0"/>
            <mass value="1" />
            <inertia ixx="100" ixy="0" ixz="0" iyy="100" iyz="0" izz="100" />
        </inertial>
        <visual>
            <origin xyz="0 0 0.12679398128200803" rpy="0 0 0"/>
            <geometry>
                <box size="0.42254380065394703 1.0468536195022116 0.25358796256401606" />
            </geometry>
            <material name="Green">
                <color rgba="0 1.0 0 1.0"/>
            </material>
        </visual>
        <collision>
            <origin xyz="0 0 0.12679398128200803" rpy="0 0 0"/>
            <geometry>
                <box size="0.42254380065394703 1.0468536195022116 0.25358796256401606" />
            </geometry>
        </collision>
    </link>
    <joint name="Apple_Person" type="revolute">
       <parent link="Apple"/>
       <child  link="Person"/>
       <origin rpy="0 0 0" xyz="0.20246150740783886 0 0.5509676927412507" />
     <axis xyz="0 1 0"/>
       <limit effort="0.0" lower="-3.14159" upper="3.14159" velocity="0.0"/>
    </joint>
    <link name="Fox">
        <inertial>
            <origin xyz="0 0.19211214793753362 0" rpy="0 0 0"/>
            <mass value="1" />
            <inertia ixx="100" ixy="0" ixz="0" iyy="100" iyz="0" izz="100" />
        </inertial>
        <visual>
            <origin xyz="0 0.19211214793753362 0" rpy="0 0 0"/>
            <geometry>
                <box size="1.8070807464824268 0.38422429587506723 0.6186167241687923" />
            </geometry>
            <material name="Green">
                <color rgba="0 1.0 0 1.0"/>
            </material>
        </visual>
        <collision>
            <origin xyz="0 0.19211214793753362 0" rpy="0 0 0"/>
            <geometry>
                <box size="1.8070807464824268 0.38422429587506723 0.6186167241687923" />
            </geometry>
        </collision>
    </link>
    <joint name="Apple_Fox" type="revolute">
       <parent link="Apple"/>
       <child  link="Fox"/>
       <origin rpy="0 0 0" xyz="0.20246150740783886 0.3711060564323818 0" />
     <axis xyz="0 1 0"/>
       <limit effort="0.0" lower="-3.14159" upper="3.14159" velocity="0.0"/>
    </joint>
</robot>