<robot name = "robot">
    <link name="Torso">
        <inertial>
            <origin xyz="-4 0 3" rpy="0 0 0"/>
            <mass value="1" />
            <inertia ixx="100" ixy="0" ixz="0" iyy="100" iyz="0" izz="100" />
        </inertial>
        <visual>
            <origin xyz="-4 0 3" rpy="0 0 0"/>
            <geometry>
                <box size="1.0423998932851426 1 1" />
            </geometry>
            <material name="Green">
                <color rgba="0 1.0 0 1.0"/>
            </material>
        </visual>
        <collision>
            <origin xyz="-4 0 3" rpy="0 0 0"/>
            <geometry>
                <box size="1.0423998932851426 1 1" />
            </geometry>
        </collision>
    </link>
    <link name="Apple">
        <inertial>
            <origin xyz="1.5612479801823425 0 0" rpy="0 0 0"/>
            <mass value="1" />
            <inertia ixx="100" ixy="0" ixz="0" iyy="100" iyz="0" izz="100" />
        </inertial>
        <visual>
            <origin xyz="1.5612479801823425 0 0" rpy="0 0 0"/>
            <geometry>
                <box size="3.122495960364685 2.585761634376578 2.2434227943166456" />
            </geometry>
            <material name="Cyan">
                <color rgba="0 1.0 1.0 1.0"/>
            </material>
        </visual>
        <collision>
            <origin xyz="1.5612479801823425 0 0" rpy="0 0 0"/>
            <geometry>
                <box size="3.122495960364685 2.585761634376578 2.2434227943166456" />
            </geometry>
        </collision>
    </link>
    <link name="Dog">
        <inertial>
            <origin xyz="0.6584502185985719 0 0" rpy="0 0 0"/>
            <mass value="1" />
            <inertia ixx="100" ixy="0" ixz="0" iyy="100" iyz="0" izz="100" />
        </inertial>
        <visual>
            <origin xyz="0.6584502185985719 0 0" rpy="0 0 0"/>
            <geometry>
                <box size="1.3169004371971438 0.9231593614757125 0.7685369570279319" />
            </geometry>
            <material name="Cyan">
                <color rgba="0 1.0 1.0 1.0"/>
            </material>
        </visual>
        <collision>
            <origin xyz="0.6584502185985719 0 0" rpy="0 0 0"/>
            <geometry>
                <box size="1.3169004371971438 0.9231593614757125 0.7685369570279319" />
            </geometry>
        </collision>
    </link>
    <link name="Person">
        <inertial>
            <origin xyz="0.0044162251280107645 0 0" rpy="0 0 0"/>
            <mass value="1" />
            <inertia ixx="100" ixy="0" ixz="0" iyy="100" iyz="0" izz="100" />
        </inertial>
        <visual>
            <origin xyz="0.0044162251280107645 0 0" rpy="0 0 0"/>
            <geometry>
                <box size="0.008832450256021529 0.5905526635692859 0.5003403740133276" />
            </geometry>
            <material name="Green">
                <color rgba="0 1.0 0 1.0"/>
            </material>
        </visual>
        <collision>
            <origin xyz="0.0044162251280107645 0 0" rpy="0 0 0"/>
            <geometry>
                <box size="0.008832450256021529 0.5905526635692859 0.5003403740133276" />
            </geometry>
        </collision>
    </link>
    <link name="Grace">
        <inertial>
            <origin xyz="0 1.884064730929777 0" rpy="0 0 0"/>
            <mass value="1" />
            <inertia ixx="100" ixy="0" ixz="0" iyy="100" iyz="0" izz="100" />
        </inertial>
        <visual>
            <origin xyz="0 1.884064730929777 0" rpy="0 0 0"/>
            <geometry>
                <box size="3.8284452887193234 3.768129461859554 1.2131912771348397" />
            </geometry>
            <material name="Ryan">
                <color rgba="0 0 0.5 1"/>
            </material>
        </visual>
        <collision>
            <origin xyz="0 1.884064730929777 0" rpy="0 0 0"/>
            <geometry>
                <box size="3.8284452887193234 3.768129461859554 1.2131912771348397" />
            </geometry>
        </collision>
    </link>
    <link name="Fox">
        <inertial>
            <origin xyz="0.8567029963743502 0 0" rpy="0 0 0"/>
            <mass value="1" />
            <inertia ixx="100" ixy="0" ixz="0" iyy="100" iyz="0" izz="100" />
        </inertial>
        <visual>
            <origin xyz="0.8567029963743502 0 0" rpy="0 0 0"/>
            <geometry>
                <box size="1.7134059927487004 1.6486806213310825 0.8633349807934727" />
            </geometry>
            <material name="Green">
                <color rgba="0 1.0 0 1.0"/>
            </material>
        </visual>
        <collision>
            <origin xyz="0.8567029963743502 0 0" rpy="0 0 0"/>
            <geometry>
                <box size="1.7134059927487004 1.6486806213310825 0.8633349807934727" />
            </geometry>
        </collision>
    </link>
    <link name="Yoojin">
        <inertial>
            <origin xyz="0 0.9516357987554402 0" rpy="0 0 0"/>
            <mass value="1" />
            <inertia ixx="100" ixy="0" ixz="0" iyy="100" iyz="0" izz="100" />
        </inertial>
        <visual>
            <origin xyz="0 0.9516357987554402 0" rpy="0 0 0"/>
            <geometry>
                <box size="0.09728570787024404 1.9032715975108805 2.7541381367815974" />
            </geometry>
            <material name="Ryan">
                <color rgba="0 0 0.5 1"/>
            </material>
        </visual>
        <collision>
            <origin xyz="0 0.9516357987554402 0" rpy="0 0 0"/>
            <geometry>
                <box size="0.09728570787024404 1.9032715975108805 2.7541381367815974" />
            </geometry>
        </collision>
    </link>
    <link name="Flower">
        <inertial>
            <origin xyz="0 0 0.9409859688157621" rpy="0 0 0"/>
            <mass value="1" />
            <inertia ixx="100" ixy="0" ixz="0" iyy="100" iyz="0" izz="100" />
        </inertial>
        <visual>
            <origin xyz="0 0 0.9409859688157621" rpy="0 0 0"/>
            <geometry>
                <box size="0.4791428362953116 0.09209163780928376 1.8819719376315243" />
            </geometry>
            <material name="Green">
                <color rgba="0 1.0 0 1.0"/>
            </material>
        </visual>
        <collision>
            <origin xyz="0 0 0.9409859688157621" rpy="0 0 0"/>
            <geometry>
                <box size="0.4791428362953116 0.09209163780928376 1.8819719376315243" />
            </geometry>
        </collision>
    </link>
    <joint name="Torso_Apple" type="revolute">
       <parent link="Torso"/>
       <child  link="Apple"/>
       <origin rpy="0 0 0" xyz="-3.478800053357429 0 3" />
     <axis xyz="0 1 0"/>
       <limit effort="0.0" lower="-3.14159" upper="3.14159" velocity="0.0"/>
    </joint>
    <joint name="Apple_Dog" type="revolute">
       <parent link="Apple"/>
       <child  link="Dog"/>
       <origin rpy="0 0 0" xyz="3.122495960364685 0 0" />
     <axis xyz="0 1 0"/>
       <limit effort="0.0" lower="-3.14159" upper="3.14159" velocity="0.0"/>
    </joint>
    <joint name="Dog_Person" type="revolute">
       <parent link="Dog"/>
       <child  link="Person"/>
       <origin rpy="0 0 0" xyz="1.3169004371971438 0 0" />
     <axis xyz="0 1 0"/>
       <limit effort="0.0" lower="-3.14159" upper="3.14159" velocity="0.0"/>
    </joint>
    <joint name="Person_Grace" type="revolute">
       <parent link="Person"/>
       <child  link="Grace"/>
       <origin rpy="0 0 0" xyz="0.0044162251280107645 0.29527633178464296 0" />
     <axis xyz="0 1 0"/>
       <limit effort="0.0" lower="-3.14159" upper="3.14159" velocity="0.0"/>
    </joint>
    <joint name="Person_Fox" type="revolute">
       <parent link="Person"/>
       <child  link="Fox"/>
       <origin rpy="0 0 0" xyz="0.008832450256021529 0 0" />
     <axis xyz="0 1 0"/>
       <limit effort="0.0" lower="-3.14159" upper="3.14159" velocity="0.0"/>
    </joint>
    <joint name="Fox_Yoojin" type="revolute">
       <parent link="Fox"/>
       <child  link="Yoojin"/>
       <origin rpy="0 0 0" xyz="0.8567029963743502 0.8243403106655413 0" />
     <axis xyz="0 1 0"/>
       <limit effort="0.0" lower="-3.14159" upper="3.14159" velocity="0.0"/>
    </joint>
    <joint name="Fox_Flower" type="revolute">
       <parent link="Fox"/>
       <child  link="Flower"/>
       <origin rpy="0 0 0" xyz="0.8567029963743502 0 0.43166749039673635" />
     <axis xyz="0 1 0"/>
       <limit effort="0.0" lower="-3.14159" upper="3.14159" velocity="0.0"/>
    </joint>
</robot>