<robot name = "robot">
    <link name="Torso">
        <inertial>
            <origin xyz="3 0 3" rpy="0 0 0"/>
            <mass value="1" />
            <inertia ixx="100" ixy="0" ixz="0" iyy="100" iyz="0" izz="100" />
        </inertial>
        <visual>
            <origin xyz="3 0 3" rpy="0 0 0"/>
            <geometry>
                <box size="1.2925999732230056 1 1" />
            </geometry>
            <material name="Cyan">
                <color rgba="0 1.0 1.0 1.0"/>
            </material>
        </visual>
        <collision>
            <origin xyz="3 0 3" rpy="0 0 0"/>
            <geometry>
                <box size="1.2925999732230056 1 1" />
            </geometry>
        </collision>
    </link>
    <joint name="Torso_Apple" type="revolute">
       <parent link="Torso"/>
       <child  link="Apple"/>
       <origin rpy="0 0 0" xyz="3.6462999866115027 0 3" />
     <axis xyz="0 1 0"/>
       <limit effort="0.0" lower="-3.14159" upper="3.14159" velocity="0.0"/>
    </joint>
    <link name="Apple">
        <inertial>
            <origin xyz="0.11685081902818295 0 0" rpy="0 0 0"/>
            <mass value="1" />
            <inertia ixx="100" ixy="0" ixz="0" iyy="100" iyz="0" izz="100" />
        </inertial>
        <visual>
            <origin xyz="0.11685081902818295 0 0" rpy="0 0 0"/>
            <geometry>
                <box size="0.2337016380563659 1.8859439852120157 3.3321346832457555" />
            </geometry>
            <material name="Cyan">
                <color rgba="0 1.0 1.0 1.0"/>
            </material>
        </visual>
        <collision>
            <origin xyz="0.11685081902818295 0 0" rpy="0 0 0"/>
            <geometry>
                <box size="0.2337016380563659 1.8859439852120157 3.3321346832457555" />
            </geometry>
        </collision>
    </link>
    <link name="Dog">
        <inertial>
            <origin xyz="0.6916557651553015 0 0" rpy="0 0 0"/>
            <mass value="1" />
            <inertia ixx="100" ixy="0" ixz="0" iyy="100" iyz="0" izz="100" />
        </inertial>
        <visual>
            <origin xyz="0.6916557651553015 0 0" rpy="0 0 0"/>
            <geometry>
                <box size="1.383311530310603 0.08750162721662003 1.8948766934368992" />
            </geometry>
            <material name="Cyan">
                <color rgba="0 1.0 1.0 1.0"/>
            </material>
        </visual>
        <collision>
            <origin xyz="0.6916557651553015 0 0" rpy="0 0 0"/>
            <geometry>
                <box size="1.383311530310603 0.08750162721662003 1.8948766934368992" />
            </geometry>
        </collision>
    </link>
    <joint name="Apple_Dog" type="revolute">
       <parent link="Apple"/>
       <child  link="Dog"/>
       <origin rpy="0 0 0" xyz="0.2337016380563659 0 0" />
     <axis xyz="0 1 0"/>
       <limit effort="0.0" lower="-3.14159" upper="3.14159" velocity="0.0"/>
    </joint>
</robot>