<robot name = "robot">
    <link name="Torso">
        <inertial>
            <origin xyz="0 0 3" rpy="0 0 0"/>
            <mass value="1" />
            <inertia ixx="100" ixy="0" ixz="0" iyy="100" iyz="0" izz="100" />
        </inertial>
        <visual>
            <origin xyz="0 0 3" rpy="0 0 0"/>
            <geometry>
                <box size="0.01843240235956478 1 1" />
            </geometry>
            <material name="Green">
                <color rgba="0 1.0 0 1.0"/>
            </material>
        </visual>
        <collision>
            <origin xyz="0 0 3" rpy="0 0 0"/>
            <geometry>
                <box size="0.01843240235956478 1 1" />
            </geometry>
        </collision>
    </link>
    <link name="Apple">
        <inertial>
            <origin xyz="0.6792636217906698 0 0" rpy="0 0 0"/>
            <mass value="1" />
            <inertia ixx="100" ixy="0" ixz="0" iyy="100" iyz="0" izz="100" />
        </inertial>
        <visual>
            <origin xyz="0.6792636217906698 0 0" rpy="0 0 0"/>
            <geometry>
                <box size="1.3585272435813396 2.6822639203602967 1.977729153117802" />
            </geometry>
            <material name="Cyan">
                <color rgba="0 1.0 1.0 1.0"/>
            </material>
        </visual>
        <collision>
            <origin xyz="0.6792636217906698 0 0" rpy="0 0 0"/>
            <geometry>
                <box size="1.3585272435813396 2.6822639203602967 1.977729153117802" />
            </geometry>
        </collision>
    </link>
    <link name="Dog">
        <inertial>
            <origin xyz="0 0.0023198914583302255 0" rpy="0 0 0"/>
            <mass value="1" />
            <inertia ixx="100" ixy="0" ixz="0" iyy="100" iyz="0" izz="100" />
        </inertial>
        <visual>
            <origin xyz="0 0.0023198914583302255 0" rpy="0 0 0"/>
            <geometry>
                <box size="0.3215255574907554 0.004639782916660451 1.968160875119159" />
            </geometry>
            <material name="Cyan">
                <color rgba="0 1.0 1.0 1.0"/>
            </material>
        </visual>
        <collision>
            <origin xyz="0 0.0023198914583302255 0" rpy="0 0 0"/>
            <geometry>
                <box size="0.3215255574907554 0.004639782916660451 1.968160875119159" />
            </geometry>
        </collision>
    </link>
    <link name="Person">
        <inertial>
            <origin xyz="0 0 0.0034515872204365916" rpy="0 0 0"/>
            <mass value="1" />
            <inertia ixx="100" ixy="0" ixz="0" iyy="100" iyz="0" izz="100" />
        </inertial>
        <visual>
            <origin xyz="0 0 0.0034515872204365916" rpy="0 0 0"/>
            <geometry>
                <box size="1.6513169573385036 1.0901032272800886 0.006903174440873183" />
            </geometry>
            <material name="Cyan">
                <color rgba="0 1.0 1.0 1.0"/>
            </material>
        </visual>
        <collision>
            <origin xyz="0 0 0.0034515872204365916" rpy="0 0 0"/>
            <geometry>
                <box size="1.6513169573385036 1.0901032272800886 0.006903174440873183" />
            </geometry>
        </collision>
    </link>
    <link name="Fox">
        <inertial>
            <origin xyz="0 0 0.2150305240161967" rpy="0 0 0"/>
            <mass value="1" />
            <inertia ixx="100" ixy="0" ixz="0" iyy="100" iyz="0" izz="100" />
        </inertial>
        <visual>
            <origin xyz="0 0 0.2150305240161967" rpy="0 0 0"/>
            <geometry>
                <box size="0.45274697544689846 0.9914908995484 0.4300610480323934" />
            </geometry>
            <material name="Cyan">
                <color rgba="0 1.0 1.0 1.0"/>
            </material>
        </visual>
        <collision>
            <origin xyz="0 0 0.2150305240161967" rpy="0 0 0"/>
            <geometry>
                <box size="0.45274697544689846 0.9914908995484 0.4300610480323934" />
            </geometry>
        </collision>
    </link>
    <link name="Flower">
        <inertial>
            <origin xyz="0 0 0.5467141290500498" rpy="0 0 0"/>
            <mass value="1" />
            <inertia ixx="100" ixy="0" ixz="0" iyy="100" iyz="0" izz="100" />
        </inertial>
        <visual>
            <origin xyz="0 0 0.5467141290500498" rpy="0 0 0"/>
            <geometry>
                <box size="0.9987752935810597 1.0816579658674805 1.0934282581000996" />
            </geometry>
            <material name="Cyan">
                <color rgba="0 1.0 1.0 1.0"/>
            </material>
        </visual>
        <collision>
            <origin xyz="0 0 0.5467141290500498" rpy="0 0 0"/>
            <geometry>
                <box size="0.9987752935810597 1.0816579658674805 1.0934282581000996" />
            </geometry>
        </collision>
    </link>
    <joint name="Torso_Apple" type="revolute">
       <parent link="Torso"/>
       <child  link="Apple"/>
       <origin rpy="0 0 0" xyz="0.00921620117978239 0 3" />
     <axis xyz="0 1 0"/>
       <limit effort="0.0" lower="-3.14159" upper="3.14159" velocity="0.0"/>
    </joint>
    <joint name="Apple_Dog" type="revolute">
       <parent link="Apple"/>
       <child  link="Dog"/>
       <origin rpy="0 0 0" xyz="1.3585272435813396 0 0" />
     <axis xyz="0 1 0"/>
       <limit effort="0.0" lower="-3.14159" upper="3.14159" velocity="0.0"/>
    </joint>
    <joint name="Dog_Person" type="revolute">
       <parent link="Dog"/>
       <child  link="Person"/>
    