<robot name = "robot">
    <joint name="Torso_Aardvark" type="revolute">
       <parent link="Torso"/>
       <child  link="Aardvark"/>
       <origin rpy="0 0 0" xyz="3.0896455066890964 0 3" />
     <axis xyz="0 1 0"/>
       <limit effort="0.0" lower="-3.14159" upper="3.14159" velocity="0.0"/>
    </joint>
    <joint name="Aardvark_Abacus" type="revolute">
       <parent link="Aardvark"/>
       <child  link="Abacus"/>
       <origin rpy="0 0 0" xyz="0.6270328287730824 0 0" />
     <axis xyz="0 1 0"/>
       <limit effort="0.0" lower="-3.14159" upper="3.14159" velocity="0.0"/>
    </joint>
    <joint name="Abacus_Abbey" type="revolute">
       <parent link="Abacus"/>
       <child  link="Abbey"/>
       <origin rpy="0 0 0" xyz="0 0 1.7354823622147495" />
     <axis xyz="0 1 0"/>
       <limit effort="0.0" lower="-3.14159" upper="3.14159" velocity="0.0"/>
    </joint>
    <joint name="Abbey_Abdomen" type="revolute">
       <parent link="Abbey"/>
       <child  link="Abdomen"/>
       <origin rpy="0 0 0" xyz="0 0.2555890960874928 0.6696977200514557" />
     <axis xyz="0 1 0"/>
       <limit effort="0.0" lower="-3.14159" upper="3.14159" velocity="0.0"/>
    </joint>
    <link name="Torso">
        <inertial>
            <origin xyz="3 0 3" rpy="0 0 0"/>
            <mass value="1" />
            <inertia ixx="100" ixy="0" ixz="0" iyy="100" iyz="0" izz="100" />
        </inertial>
        <visual>
            <origin xyz="3 0 3" rpy="0 0 0"/>
            <geometry>
                <box size="0.3448317697686145 0.8951479384410852 1.356132641466123" />
            </geometry>
            <material name="Cyan">
                <color rgba="0 1.0 1.0 1.0"/>
            </material>
        </visual>
        <collision>
            <origin xyz="3 0 3" rpy="0 0 0"/>
            <geometry>
                <box size="0.3448317697686145 0.8951479384410852 1.356132641466123" />
            </geometry>
        </collision>
    </link>
    <link name="Aardvark">
        <inertial>
            <origin xyz="0.3135164143865412 0 0" rpy="0 0 0"/>
            <mass value="1" />
            <inertia ixx="100" ixy="0" ixz="0" iyy="100" iyz="0" izz="100" />
        </inertial>
        <visual>
            <origin xyz="0.3135164143865412 0 0" rpy="0 0 0"/>
            <geometry>
                <box size="0.6270328287730824 0.08962853636233303 0.07417319373955866" />
            </geometry>
            <material name="Cyan">
                <color rgba="0 1.0 1.0 1.0"/>
            </material>
        </visual>
        <collision>
            <origin xyz="0.3135164143865412 0 0" rpy="0 0 0"/>
            <geometry>
                <box size="0.6270328287730824 0.08962853636233303 0.07417319373955866" />
            </geometry>
        </collision>
    </link>
    <link name="Abacus">
        <inertial>
            <origin xyz="0 0 0.8677411811073747" rpy="0 0 0"/>
            <mass value="1" />
            <inertia ixx="100" ixy="0" ixz="0" iyy="100" iyz="0" izz="100" />
        </inertial>
        <visual>
            <origin xyz="0 0 0.8677411811073747" rpy="0 0 0"/>
            <geometry>
                <box size="0.7901424532921679 0.3200411760598658 1.7354823622147495" />
            </geometry>
            <material name="Cyan">
                <color rgba="0 1.0 1.0 1.0"/>
            </material>
        </visual>
        <collision>
            <origin xyz="0 0 0.8677411811073747" rpy="0 0 0"/>
            <geometry>
                <box size="0.7901424532921679 0.3200411760598658 1.7354823622147495" />
            </geometry>
        </collision>
    </link>
    <link name="Abbey">
        <inertial>
            <origin xyz="0 0 0.6696977200514557" rpy="0 0 0"/>
            <mass value="1" />
            <inertia ixx="100" ixy="0" ixz="0" iyy="100" iyz="0" izz="100" />
        </inertial>
        <visual>
            <origin xyz="0 0 0.6696977200514557" rpy="0 0 0"/>
            <geometry>
                <box size="1.3972364917198317 0.5111781921749856 1.3393954401029113" />
            </geometry>
            <material name="Cyan">
                <color rgba="0 1.0 1.0 1.0"/>
            </material>
        </visual>
        <collision>
            <origin xyz="0 0 0.6696977200514557" rpy="0 0 0"/>
            <geometry>
                <box size="1.3972364917198317 0.5111781921749856 1.3393954401029113" />
            </geometry>
        </collision>
    </link>
    <link name="Abdomen">
        <inertial>
            <origin xyz="0 0.64664361950223 0" rpy="0 0 0"/>
            <mass value="1" />
            <inertia ixx="100" ixy="0" ixz="0" iyy="100" iyz="0" izz="100" />
        </inertial>
        <visual>
            <origin xyz="0 0.64664361950223 0" rpy="0 0 0"/>
            <geometry>
                <box size="1.5890504990343906 1.29328723900446 1.3550236345521927" />
            </geometry>
            <material name="Cyan">
                <color rgba="0 1.0 1.0 1.0"/>
            </material>
        </visual>
        <collision>
            <origin xyz="0 0.64664361950223 0" rpy="0 0 0"/>
            <geometry>
                <box size="1.5890504990343906 1.29328723900446 1.3550236345521927" />
            </geometry>
        </collision>
    </link>
</robot>