<robot name = "robot">
    <link name="Torso">
        <inertial>
            <origin xyz="-1 0 3" rpy="0 0 0"/>
            <mass value="1" />
            <inertia ixx="100" ixy="0" ixz="0" iyy="100" iyz="0" izz="100" />
        </inertial>
        <visual>
            <origin xyz="-1 0 3" rpy="0 0 0"/>
            <geometry>
                <box size="0.1339647526360388 1 1" />
            </geometry>
            <material name="Cyan">
                <color rgba="0 1.0 1.0 1.0"/>
            </material>
        </visual>
        <collision>
            <origin xyz="-1 0 3" rpy="0 0 0"/>
            <geometry>
                <box size="0.1339647526360388 1 1" />
            </geometry>
        </collision>
    </link>
    <joint name="Torso_Apple" type="revolute">
       <parent link="Torso"/>
       <child  link="Apple"/>
       <origin rpy="0 0 0" xyz="-0.9330176236819806 0 3" />
     <axis xyz="0 1 0"/>
       <limit effort="0.0" lower="-3.14159" upper="3.14159" velocity="0.0"/>
    </joint>
    <link name="Apple">
        <inertial>
            <origin xyz="0.7742297315304206 0 0" rpy="0 0 0"/>
            <mass value="1" />
            <inertia ixx="100" ixy="0" ixz="0" iyy="100" iyz="0" izz="100" />
        </inertial>
        <visual>
            <origin xyz="0.7742297315304206 0 0" rpy="0 0 0"/>
            <geometry>
                <box size="1.5484594630608413 0.10547728106503129 1.2840350188108556" />
            </geometry>
            <material name="Green">
                <color rgba="0 1.0 0 1.0"/>
            </material>
        </visual>
        <collision>
            <origin xyz="0.7742297315304206 0 0" rpy="0 0 0"/>
            <geometry>
                <box size="1.5484594630608413 0.10547728106503129 1.2840350188108556" />
            </geometry>
        </collision>
    </link>
    <link name="Dog">
        <inertial>
            <origin xyz="0.0388523389597365 0 0" rpy="0 0 0"/>
            <mass value="1" />
            <inertia ixx="100" ixy="0" ixz="0" iyy="100" iyz="0" izz="100" />
        </inertial>
        <visual>
            <origin xyz="0.0388523389597365 0 0" rpy="0 0 0"/>
            <geometry>
                <box size="0.077704677919473 1.9113699971109968 0.4115862454085284" />
            </geometry>
            <material name="Cyan">
                <color rgba="0 1.0 1.0 1.0"/>
            </material>
        </visual>
        <collision>
            <origin xyz="0.0388523389597365 0 0" rpy="0 0 0"/>
            <geometry>
                <box size="0.077704677919473 1.9113699971109968 0.4115862454085284" />
            </geometry>
        </collision>
    </link>
    <joint name="Apple_Dog" type="revolute">
       <parent link="Apple"/>
       <child  link="Dog"/>
       <origin rpy="0 0 0" xyz="1.5484594630608413 0 0" />
     <axis xyz="0 1 0"/>
       <limit effort="0.0" lower="-3.14159" upper="3.14159" velocity="0.0"/>
    </joint>
    <link name="Person">
        <inertial>
            <origin xyz="0.46498086929062943 0 0" rpy="0 0 0"/>
            <mass value="1" />
            <inertia ixx="100" ixy="0" ixz="0" iyy="100" iyz="0" izz="100" />
        </inertial>
        <visual>
            <origin xyz="0.46498086929062943 0 0" rpy="0 0 0"/>
            <geometry>
                <box size="0.9299617385812589 0.2309725123194224 1.9970964847245363" />
            </geometry>
            <material name="Cyan">
                <color rgba="0 1.0 1.0 1.0"/>
            </material>
        </visual>
        <collision>
            <origin xyz="0.46498086929062943 0 0" rpy="0 0 0"/>
            <geometry>
                <box size="0.9299617385812589 0.2309725123194224 1.9970964847245363" />
            </geometry>
        </collision>
    </link>
    <joint name="Dog_Person" type="revolute">
       <parent link="Dog"/>
       <child  link="Person"/>
       <origin rpy="0 0 0" xyz="0.077704677919473 0 0" />
     <axis xyz="0 1 0"/>
       <limit effort="0.0" lower="-3.14159" upper="3.14159" velocity="0.0"/>
    </joint>
    <link name="Fox">
        <inertial>
            <origin xyz="0.2450813475855943 0 0" rpy="0 0 0"/>
            <mass value="1" />
            <inertia ixx="100" ixy="0" ixz="0" iyy="100" iyz="0" izz="100" />
        </inertial>
        <visual>
            <origin xyz="0.2450813475855943 0 0" rpy="0 0 0"/>
            <geometry>
                <box size="0.4901626951711886 1.42579429715745 0.6253533667884623" />
            </geometry>
            <material name="Green">
                <color rgba="0 1.0 0 1.0"/>
            </material>
        </visual>
        <collision>
            <origin xyz="0.2450813475855943 0 0" rpy="0 0 0"/>
            <geometry>
                <box size="0.4901626951711886 1.42579429715745 0.6253533667884623" />
            </geometry>
        </collision>
    </link>
    <joint name="Person_Fox" type="revolute">
       <parent link="Person"/>
       <child  link="Fox"/>
       <origin rpy="0 0 0" xyz="0.9299617385812589 0 0" />
     <axis xyz="0 1 0"/>
       <limit effort="0.0" lower="-3.14159" upper="3.14159" velocity="0.0"/>
    </joint>
    <link name="Flower">
        <inertial>
            <origin xyz="0.5265148441051062 0 0" rpy="0 0 0"/>
            <mass value="1" />
            <inertia ixx="100" ixy="0" ixz="0" iyy="100" iyz="0" izz="100" />
        </inertial>
        <visual>
            <origin xyz="0.5265148441051062 0 0" rpy="0 0 0"/>
            <geometry>
                <box size="1.0530296882102124 0.8761855061743382 1.393009351659914" />
            </geometry>
            <material name="Cyan">
                <color rgba="0 1.0 1.0 1.0"/>
            </material>
        </visual>
        <collision>
            <origin xyz="0.5265148441051062 0 0" rpy="0 0 0"/>
            <geometry>
                <box size="1.0530296882102124 0.8761855061743382 1.393009351659914" />
            </geometry>
        </collision>
    </link>
    <joint name="Fox_Flower" type="revolute">
       <parent link="Fox"/>
       <child  link="Flower"/>
       <origin rpy="0 0 0" xyz="0.4901626951711886 0 0" />
     <axis xyz="0 1 0"/>
       <limit effort="0.0" lower="-3.14159" upper="3.14159" velocity="0.0"/>
    </joint>
    <link name="Neighbor">
        <inertial>
            <origin xyz="0.9316082158733014 0 0" rpy="0 0 0"/>
            <mass value="1" />
            <inertia ixx="100" ixy="0" ixz="0" iyy="100" iyz="0" izz="100" />
        </inertial>
        <visual>
            <origin xyz="0.9316082158733014 0 0" rpy="0 0 0"/>
            <geometry>
                <box size="1.863216431746603 0.3053266239894876 0.6852136294179394" />
            </geometry>
            <material name="Green">
                <color rgba="0 1.0 0 1.0"/>
            </material>
        </visual>
        <collision>
            <origin xyz="0.9316082158733014 0 0" rpy="0 0 0"/>
            <geometry>
                <box size="1.863216431746603 0.3053266239894876 0.6852136294179394" />
            </geometry>
        </collision>
    </link>
    <joint name="Flower_Neighbor" type="revolute">
       <parent link="Flower"/>
       <child  link="Neighbor"/>
       <origin rpy="0 0 0" xyz="1.0530296882102124 0 0" />
     <axis xyz="0 1 0"/>
       <limit effort="0.0" lower="-3.14159" upper="3.14159" velocity="0.0"/>
    </joint>
    <link name="Coffee">
        <inertial>
            <origin xyz="0.23300251940940497 0 0" rpy="0 0 0"/>
            <mass value="1" />
            <inertia ixx="100" ixy="0" ixz="0" iyy="100" iyz="0" izz="100" />
        </inertial>
        <visual>
            <origin xyz="0.23300251940940497 0 0" rpy="0 0 0"/>
            <geometry>
                <box size="0.46600503881880995 1.3144505152611807 1.7584620044147339" />
            </geometry>
            <material name="Green">
                <color rgba="0 1.0 0 1.0"/>
            </material>
        </visual>
        <collision>
            <origin xyz="0.23300251940940497 0 0" rpy="0 0 0"/>
            <geometry>
                <box size="0.46600503881880995 1.3144505152611807 1.7584620044147339" />
            </geometry>
        </collision>
    </link>
    <joint name="Neighbor_Coffee" type="revolute">
       <parent link="Neighbor"/>
       <child  link="Coffee"/>
       <origin rpy="0 0 0" xyz="1.863216431746603 0 0" />
     <axis xyz="0 1 0"/>
       <limit effort="0.0" lower="-3.14159" upper="3.14159" velocity="0.0"/>
    </joint>
</robot>