<robot name = "robot">
    <joint name="Torso_Aardvark" type="revolute">
       <parent link="Torso"/>
       <child  link="Aardvark"/>
       <origin rpy="0 0 0" xyz="-1.552728738325754 0 3" />
     <axis xyz="0 1 0"/>
       <limit effort="0.0" lower="-3.14159" upper="3.14159" velocity="0.0"/>
    </joint>
    <joint name="Aardvark_Abacus" type="revolute">
       <parent link="Aardvark"/>
       <child  link="Abacus"/>
       <origin rpy="0 0 0" xyz="3.9363384728317157 0 0" />
     <axis xyz="0 1 0"/>
       <limit effort="0.0" lower="-3.14159" upper="3.14159" velocity="0.0"/>
    </joint>
    <joint name="Abacus_Abbey" type="revolute">
       <parent link="Abacus"/>
       <child  link="Abbey"/>
       <origin rpy="0 0 0" xyz="0.13731352987386325 0 0.9825621912264036" />
     <axis xyz="0 1 0"/>
       <limit effort="0.0" lower="-3.14159" upper="3.14159" velocity="0.0"/>
    </joint>
    <joint name="Abbey_Abdomen" type="revolute">
       <parent link="Abbey"/>
       <child  link="Abdomen"/>
       <origin rpy="0 0 0" xyz="0.910575846797863 0 0.31743328195625786" />
     <axis xyz="0 1 0"/>
       <limit effort="0.0" lower="-3.14159" upper="3.14159" velocity="0.0"/>
    </joint>
    <link name="Torso">
        <inertial>
            <origin xyz="-1.8185229944302712 0 3" rpy="0 0 0"/>
            <mass value="1" />
            <inertia ixx="100" ixy="0" ixz="0" iyy="100" iyz="0" izz="100" />
        </inertial>
        <visual>
            <origin xyz="-1.8185229944302712 0 3" rpy="0 0 0"/>
            <geometry>
                <box size="0.5315885122090345 1.856482849275269 0.8012767000097856" />
            </geometry>
            <material name="Green">
                <color rgba="0 1.0 0 1.0"/>
            </material>
        </visual>
        <collision>
            <origin xyz="-1.8185229944302712 0 3" rpy="0 0 0"/>
            <geometry>
                <box size="0.5315885122090345 1.856482849275269 0.8012767000097856" />
            </geometry>
        </collision>
    </link>
    <link name="Aardvark">
        <inertial>
            <origin xyz="1.9681692364158578 0 0" rpy="0 0 0"/>
            <mass value="1" />
            <inertia ixx="100" ixy="0" ixz="0" iyy="100" iyz="0" izz="100" />
        </inertial>
        <visual>
            <origin xyz="1.9681692364158578 0 0" rpy="0 0 0"/>
            <geometry>
                <box size="3.9363384728317157 0.13696371380342853 1.6518209906137868" />
            </geometry>
            <material name="Cyan">
                <color rgba="0 1.0 1.0 1.0"/>
            </material>
        </visual>
        <collision>
            <origin xyz="1.9681692364158578 0 0" rpy="0 0 0"/>
            <geometry>
                <box size="3.9363384728317157 0.13696371380342853 1.6518209906137868" />
            </geometry>
        </collision>
    </link>
    <link name="Abacus">
        <inertial>
            <origin xyz="0.13731352987386325 0 0" rpy="0 0 0"/>
            <mass value="1" />
            <inertia ixx="100" ixy="0" ixz="0" iyy="100" iyz="0" izz="100" />
        </inertial>
        <visual>
            <origin xyz="0.13731352987386325 0 0" rpy="0 0 0"/>
            <geometry>
                <box size="0.2746270597477265 0.8162073829157213 1.9651243824528073" />
            </geometry>
            <material name="Green">
                <color rgba="0 1.0 0 1.0"/>
            </material>
        </visual>
        <collision>
            <origin xyz="0.13731352987386325 0 0" rpy="0 0 0"/>
            <geometry>
                <box size="0.2746270597477265 0.8162073829157213 1.9651243824528073" />
            </geometry>
        </collision>
    </link>
    <link name="Abbey">
        <inertial>
            <origin xyz="0 0 0.31743328195625786" rpy="0 0 0"/>
            <mass value="1" />
            <inertia ixx="100" ixy="0" ixz="0" iyy="100" iyz="0" izz="100" />
        </inertial>
        <visual>
            <origin xyz="0 0 0.31743328195625786" rpy="0 0 0"/>
            <geometry>
                <box size="1.821151693595726 1.288966503280712 0.6348665639125157" />
            </geometry>
            <material name="Cyan">
                <color rgba="0 1.0 1.0 1.0"/>
            </material>
        </visual>
        <collision>
            <origin xyz="0 0 0.31743328195625786" rpy="0 0 0"/>
            <geometry>
                <box size="1.821151693595726 1.288966503280712 0.6348665639125157" />
            </geometry>
        </collision>
    </link>
    <link name="Abdomen">
        <inertial>
            <origin xyz="0.7590902308910626 0 0" rpy="0 0 0"/>
            <mass value="1" />
            <inertia ixx="100" ixy="0" ixz="0" iyy="100" iyz="0" izz="100" />
        </inertial>
        <visual>
            <origin xyz="0.7590902308910626 0 0" rpy="0 0 0"/>
            <geometry>
                <box size="1.5181804617821253 1.7314448215940077 0.7845046480229252" />
            </geometry>
            <material name="Green">
                <color rgba="0 1.0 0 1.0"/>
            </material>
        </visual>
        <collision>
            <origin xyz="0.7590902308910626 0 0" rpy="0 0 0"/>
            <geometry>
                <box size="1.5181804617821253 1.7314448215940077 0.7845046480229252" />
            </geometry>
        </collision>
    </link>
</robot>