<robot name = "robot">
    <link name="Torso">
        <inertial>
            <origin xyz="1 0 3" rpy="0 0 0"/>
            <mass value="1" />
            <inertia ixx="100" ixy="0" ixz="0" iyy="100" iyz="0" izz="100" />
        </inertial>
        <visual>
            <origin xyz="1 0 3" rpy="0 0 0"/>
            <geometry>
                <box size="1.4982470538409607 1 1" />
            </geometry>
            <material name="Green">
                <color rgba="0 1.0 0 1.0"/>
            </material>
        </visual>
        <collision>
            <origin xyz="1 0 3" rpy="0 0 0"/>
            <geometry>
                <box size="1.4982470538409607 1 1" />
            </geometry>
        </collision>
    </link>
    <link name="Dog">
        <inertial>
            <origin xyz="0.6055435879003438 0.03295924861530297 0.5089174926389667" rpy="0 0 0"/>
            <mass value="1" />
            <inertia ixx="100" ixy="0" ixz="0" iyy="100" iyz="0" izz="100" />
        </inertial>
        <visual>
            <origin xyz="0.6055435879003438 0.03295924861530297 0.5089174926389667" rpy="0 0 0"/>
            <geometry>
                <box size="1.2110871758006876 0.06591849723060594 1.0178349852779334" />
            </geometry>
            <material name="Green">
                <color rgba="0 1.0 0 1.0"/>
            </material>
        </visual>
        <collision>
            <origin xyz="0.6055435879003438 0.03295924861530297 0.5089174926389667" rpy="0 0 0"/>
            <geometry>
                <box size="1.2110871758006876 0.06591849723060594 1.0178349852779334" />
            </geometry>
        </collision>
    </link>
    <joint name="Torso_Dog" type="revolute">
       <parent link="Torso"/>
       <child  link="Dog"/>
       <origin rpy="0 0 0" xyz="1.7491235269204803 0 3" />
     <axis xyz="0 1 0"/>
       <limit effort="0.0" lower="-3.14159" upper="3.14159" velocity="0.0"/>
    </joint>
</robot>